  0%|                                                                                                                                                 | 0/12 [00:00<?, ?it/s]Traceback (most recent call last):
  File "/workspace/llm_project/src/modeling/train.py", line 71, in <module>
    main()
  File "/workspace/llm_project/src/modeling/train.py", line 66, in main
    trainer.train()
  File "/usr/local/lib/python3.11/dist-packages/transformers/trainer.py", line 2245, in train
    return inner_training_loop(
           ^^^^^^^^^^^^^^^^^^^^
  File "/usr/local/lib/python3.11/dist-packages/transformers/trainer.py", line 2560, in _inner_training_loop
    tr_loss_step = self.training_step(model, inputs, num_items_in_batch)
                   ^^^^^^^^^^^^^^^^^^^^^^^^^^^^^^^^^^^^^^^^^^^^^^^^^^^^^
  File "/usr/local/lib/python3.11/dist-packages/transformers/trainer.py", line 3782, in training_step
    self.accelerator.backward(loss, **kwargs)
  File "/usr/local/lib/python3.11/dist-packages/accelerate/accelerator.py", line 2450, in backward
    self.scaler.scale(loss).backward(**kwargs)
  File "/usr/local/lib/python3.11/dist-packages/torch/_tensor.py", line 648, in backward
    torch.autograd.backward(
  File "/usr/local/lib/python3.11/dist-packages/torch/autograd/__init__.py", line 353, in backward
    _engine_run_backward(
  File "/usr/local/lib/python3.11/dist-packages/torch/autograd/graph.py", line 824, in _engine_run_backward
    return Variable._execution_engine.run_backward(  # Calls into the C++ engine to run the backward pass
           ^^^^^^^^^^^^^^^^^^^^^^^^^^^^^^^^^^^^^^^^^^^^^^^^^^^^^^^^^^^^^^^^^^^^^^^^^^^^^^^^^^^^^^^^^^^^^^
RuntimeError: CUDA error: CUBLAS_STATUS_ALLOC_FAILED when calling `cublasCreate(handle)`
